Workbook

Sheet Assumptions
A1: SHAPE CERTO — ASSUMPTIONS (Plano de Negócios SaaS)
A2: Última atualização: Mai 2026 | Câmbio: USD 1 = BRL na célula B5 | AZUL = inputs editáveis | PRETO = fórmulas
A3: A. MACRO & CÂMBIO
A4: Parâmetro | B4: Valor | C4: Fonte / Nota
A5: Câmbio USD → BRL (atual) | B5: 5.7 | C5: Referência Mai 2026 — atualizar mensalmente
A6: Câmbio mês anterior (USD → BRL) | B6: 5.7 | C6: Copiar câmbio atual antes de atualizar B5
A7: Variação câmbio (%) | B7: =IF(B6>0,(B5-B6)/B6,0) | C7: Calculado automaticamente
A9: B. OPENAI API — PREÇOS (USD por 1 M tokens)
A10: Modelo | B10: Preço USD/1M tk | C10: Nota
A11: GPT-4o-mini — Input | B11: 0.15 | C11: Preço atual Mai 2026 — openai.com/pricing
A12: GPT-4o-mini — Output | B12: 0.6 | C12: Preço atual Mai 2026 — openai.com/pricing
A14: C. STRIPE — TAXAS
A15: Parâmetro | B15: Valor | C15: Nota
A16: Taxa percentual Brasil (%) | B16: 0.0399 | C16: 3.99% — cartão nacional BR
A17: Taxa fixa Brasil (R$) | B17: 0.39 | C17: R$0.39 por transação
A18: Taxa percentual Intl (%) | B18: 0.029 | C18: 2.9% — cartão internacional
A19: Taxa fixa Internacional ($) | B19: 0.3 | C19: $0.30 por transação
A21: D. INFRAESTRUTURA — CUSTOS FIXOS MENSAIS (USD)
A22: Componente | B22: USD/mês | C22: Nota
A23: Servidor VPS/Cloud | B23: 30 | C23: Mid-range VPS — escala até ~500 usuários
A24: Banco de dados Postgres | B24: 20 | C24: Managed Postgres
A25: Storage S3 base (USD) | B25: 5 | C25: ~200 GB base de fotos
A26: S3 custo por GB extra ($) | B26: 0.023 | C26: USD/GB além da base
A27: CDN / Bandwidth | B27: 5 | C27: Estimativa transferência
A28: Monitoring / Logs | B28: 5 | C28: Datadog ou similar — básico
A29: TOTAL INFRA FIXO BASE/MÊS (USD) | B29: =SUM(B23:B28) | C29: Base — escala com mais servidores
A30: D2. STORAGE POR USUÁRIO (fotos — GB/mês estimado)
A31: Plano | B31: GB/usuário/mês | C31: Nota
A32: Básico (2 fotos/semana, ~0.5MB) | B32: 0.004 | C32: ~8 fotos × 0.5MB = 4MB/mês
A33: Intermediário (6 fotos/check-in semanal) | B33: 0.012 | C33: ~24 fotos × 0.5MB = 12MB/mês
A34: Pro (ilimitado — estimativa 40 fotos/mês) | B34: 0.02 | C34: ~40 fotos × 0.5MB = 20MB/mês
A36: E. TOKENS INPUT POR MENSAGEM DE CHAT (contexto)
A37: Plano | B37: Tokens Input/msg | C37: Nota
A38: Básico — contexto comprimido | B38: 2000 | C38: Perfil básico por msg
A39: Intermediário — contexto médio | B39: 8000 | C39: Histórico + medidas corporais
A40: Pro — contexto completo | B40: 18000 | C40: Histórico completo + bioimpedância
A42: E2. OUTPUT MÉDIO POR RESPOSTA DO CHAT (tokens)
A43: Plano | B43: Tokens Output/msg | C43: Nota
A44: Básico | B44: 350 | C44: Respostas curtas / simples
A45: Intermediário | B45: 450 | C45: Respostas moderadas
...

Sheet Token_Costs
A1: CUSTOS DE TOKENS — OpenAI GPT-4o-mini por Usuário/Mês
A2: Azul = inputs | Preto = fórmulas linkadas de Assumptions | Colunas C-D = valores token | E-H = custos USD e BRL
A3: PLANO BÁSICO
A4: Métrica | B4: Driver / Fórmula | C4: Conservador (qtd) | D4: Moderado (qtd) | E4: Cons. Custo USD | F4: Mod. Custo USD | G4: Cons. Custo BRL | H4: Mod. Custo BRL
A5: Dias no mês | B5: Fixo = 30 dias | C5: 30 | D5: 30 | E5: — | F5: — | G5: — | H5: —
A6: Mensagens/dia (chat) | B6: Assumptions E4 — linha 56 | C6: =Assumptions!B56 | D6: =Assumptions!C56 | E6: — | F6: — | G6: — | H6: —
A7: Total mensagens/mês | B7: = msgs/dia × 30 | C7: =C6*C5 | D7: =D6*D5 | E7: — | F7: — | G7: — | H7: —
A8: Tokens input/msg (contexto comprimido) | B8: Assumptions E — linha 38 | C8: =Assumptions!B38 | D8: =Assumptions!B38 | E8: — | F8: — | G8: — | H8: —
A9: Tokens output/resposta | B9: Assumptions E2 — linha 44 | C9: =Assumptions!B44 | D9: =Assumptions!B44 | E9: — | F9: — | G9: — | H9: —
A10: Gerações IA (dieta+treino) por mês | B10: Assumptions E5 — linha 62 | C10: =Assumptions!B62 | D10: =Assumptions!C62 | E10: — | F10: — | G10: — | H10: —
A11: Tokens input por geração IA | B11: Assumptions E3 — linha 50 | C11: =Assumptions!B50 | D11: =Assumptions!B50 | E11: — | F11: — | G11: — | H11: —
A12: Tokens output por geração IA | B12: Assumptions E3 col C — linha 50 | C12: =Assumptions!C50 | D12: =Assumptions!C50 | E12: — | F12: — | G12: — | H12: —
A13: TOTAL tokens input/mês | B13: = msgs×ctx_input + gerações×tok_in_ger | C13: =C7*C8+C10*C11 | D13: =D7*D8+D10*D11 | E13: =C13/1000000*Assumptions!B11 | F13: =D13/1000000*Assumptions!B11 | G13: =E13*Assumptions!B5 | H13: =F13*Assumptions!B5
A14: TOTAL tokens output/mês | B14: = msgs×tok_output + gerações×tok_out_ger | C14: =C7*C9+C10*C12 | D14: =D7*D9+D10*D12 | E14: =C14/1000000*Assumptions!B12 | F14: =D14/1000000*Assumptions!B12 | G14: =E14*Assumptions!B5 | H14: =F14*Assumptions!B5
A15: CUSTO OPENAI TOTAL (USD e BRL/usuário/mês) | B15: = custo_input + custo_output | C15: =C13/1000000*Assumptions!B11+C14/1000000*Assumptions!B12 | D15: =D13/1000000*Assumptions!B11+D14/1000000*Assumptions!B12 | E15: =C15 | F15: =D15 | G15: =C15*Assumptions!B5 | H15: =D15*Assumptions!B5
A18: PLANO INTERMEDIÁRIO
A19: Métrica | B19: Driver / Fórmula | C19: Conservador (qtd) | D19: Moderado (qtd) | E19: Cons. Custo USD | F19: Mod. Custo USD | G19: Cons. Custo BRL | H19: Mod. Custo BRL
A20: Dias no mês | B20: Fixo = 30 dias | C20: 30 | D20: 30 | E20: — | F20: — | G20: — | H20: —
A21: Mensagens/dia (chat) | B21: Assumptions E4 — linha 57 | C21: =Assumptions!B57 | D21: =Assumptions!C57 | E21: — | F21: — | G21: — | H21: —
A22: Total mensagens/mês | B22: = msgs/dia × 30 | C22: =C21*C20 | D22: =D21*D20 | E22: — | F22: — | G22: — | H22: —
A23: Tokens input/msg (contexto comprimido) | B23: Assumptions E — linha 39 | C23: =Assumptions!B39 | D23: =Assumptions!B39 | E23: — | F23: — | G23: — | H23: —
A24: Tokens output/resposta | B24: Assumptions E2 — linha 45 | C24: =Assumptions!B45 | D24: =Assumptions!B45 | E24: — | F24: — | G24: — | H24: —
A25: Gerações IA (dieta+treino) por mês | B25: Assumptions E5 — linha 63 | C25: =Assumptions!B63 | D25: =Assumptions!C63 | E25: — | F25: — | G25: — | H25: —
A26: Tokens input por geração IA | B26: Assumptions E3 — linha 51 | C26: =Assumptions!B51 | D26: =Assumptions!B51 | E26: — | F26: — | G26: — | H26: —
A27: Tokens output por geração IA | B27: Assumptions E3 col C — linha 51 | C27: =Assumptions!C51 | D27: =Assumptions!C51 | E27: — | F27: — | G27: — | H27: —
A28: TOTAL tokens input/mês | B28: = msgs×ctx_input + gerações×tok_in_ger | C28: =C22*C23+C25*C26 | D28: =D22*D23+D25*D26 | E28: =C28/1000000*Assumptions!B11 | F28: =D28/1000000*Assumptions!B11 | G28: =E28*Assumptions!B5 | H28: =F28*Assumptions!B5
A29: TOTAL tokens output/mês | B29: = msgs×tok_output + gerações×tok_out_ger | C29: =C22*C24+C25*C27 | D29: =D22*D24+D25*D27 | E29: =C29/1000000*Assumptions!B12 | F29: =D29/1000000*Assumptions!B12 | G29: =E29*Assumptions!B5 | H29: =F29*Assumptions!B5
A30: CUSTO OPENAI TOTAL (USD e BRL/usuário/mês) | B30: = custo_input + custo_output | C30: =C28/1000000*Assumptions!B11+C29/1000000*Assumptions!B12 | D30: =D28/1000000*Assumptions!B11+D29/1000000*Assumptions!B12 | E30: =C30 | F30: =D30 | G30: =C30*Assumptions!B5 | H30: =D30*Assumptions!B5
A33: PLANO PRO
A34: Métrica | B34: Driver / Fórmula | C34: Conservador (qtd) | D34: Moderado (qtd) | E34: Cons. Custo USD | F34: Mod. Custo USD | G34: Cons. Custo BRL | H34: Mod. Custo BRL
A35: Dias no mês | B35: Fixo = 30 dias | C35: 30 | D35: 30 | E35: — | F35: — | G35: — | H35: —
A36: Mensagens/dia (chat) | B36: Assumptions E4 — linha 58 | C36: =Assumptions!B58 | D36: =Assumptions!C58 | E36: — | F36: — | G36: — | H36: —
A37: Total mensagens/mês | B37: = msgs/dia × 30 | C37: =C36*C35 | D37: =D36*D35 | E37: — | F37: — | G37: — | H37: —
A38: Tokens input/msg (contexto comprimido) | B38: Assumptions E — linha 40 | C38: =Assumptions!B40 | D38: =Assumptions!B40 | E38: — | F38: — | G38: — | H38: —
A39: Tokens output/resposta | B39: Assumptions E2 — linha 46 | C39: =Assumptions!B46 | D39: =Assumptions!B46 | E39: — | F39: — | G39: — | H39: —
A40: Gerações IA (dieta+treino) por mês | B40: Assumptions E5 — linha 64 | C40: =Assumptions!B64 | D40: =Assumptions!C64 | E40: — | F40: — | G40: — | H40: —
A41: Tokens input por geração IA | B41: Assumptions E3 — linha 52 | C41: =Assumptions!B52 | D41: =Assumptions!B52 | E41: — | F41: — | G41: — | H41: —
A42: Tokens output por geração IA | B42: Assumptions E3 col C — linha 52 | C42: =Assumptions!C52 | D42: =Assumptions!C52 | E42: — | F42: — | G42: — | H42: —
A43: TOTAL tokens input/mês | B43: = msgs×ctx_input + gerações×tok_in_ger | C43: =C37*C38+C40*C41 | D43: =D37*D38+D40*D41 | E43: =C43/1000000*Assumptions!B11 | F43: =D43/1000000*Assumptions!B11 | G43: =E43*Assumptions!B5 | H43: =F43*Assumptions!B5
A44: TOTAL tokens output/mês | B44: = msgs×tok_output + gerações×tok_out_ger | C44: =C37*C39+C40*C42 | D44: =D37*D39+D40*D42 | E44: =C44/1000000*Assumptions!B12 | F44: =D44/1000000*Assumptions!B12 | G44: =E44*Assumptions!B5 | H44: =F44*Assumptions!B5
...

Sheet Infra_Costs
A1: CUSTOS DE INFRAESTRUTURA por Usuário/Mês em Diferentes Escalas
A2: Custos fixos de Assumptions. S3 escala com número de usuários e mix de planos.
A3: CUSTO INFRA MENSAL TOTAL (USD) — por escala de usuários
A4: Componente | B4: 100 Usuários | C4: 500 Usuários | D4: 1.000 Usuários | E4: 2.000 Usuários
A5: Servidor / VPS (escala c/ mais instâncias) | B5: =Assumptions!B23*1 | C5: =Assumptions!B23*1 | D5: =Assumptions!B23*2 | E5: =Assumptions!B23*3
A6: Banco de dados Postgres | B6: =Assumptions!B24 | C6: =Assumptions!B24 | D6: =Assumptions!B24 | E6: =Assumptions!B24
A7: Storage S3 (base + fotos por usuários — mix 50/35/15) | B7: =Assumptions!B25+(0.5*Assumptions!B32+0.35*Assumptions!B33+0.15*Assumptions!B34)*100*Assumptions!B26 | C7: =Assumptions!B25+(0.5*Assumptions!B32+0.35*Assumptions!B33+0.15*Assumptions!B34)*500*Assumptions!B26 | D7: =Assumptions!B25+(0.5*Assumptions!B32+0.35*Assumptions!B33+0.15*Assumptions!B34)*1000*Assumptions!B26 | E7: =Assumptions!B25+(0.5*Assumptions!B32+0.35*Assumptions!B33+0.15*Assumptions!B34)*2000*Assumptions!B26
A8: CDN / Bandwidth | B8: =Assumptions!B27*1 | C8: =Assumptions!B27*1 | D8: =Assumptions!B27*2 | E8: =Assumptions!B27*2
A9: Monitoring / Logs | B9: =Assumptions!B28*1 | C9: =Assumptions!B28*1 | D9: =Assumptions!B28*1 | E9: =Assumptions!B28*2
A10: TOTAL INFRA MENSAL (USD) | B10: =SUM(B5:B9) | C10: =SUM(C5:C9) | D10: =SUM(D5:D9) | E10: =SUM(E5:E9)
A12: CUSTO INFRA POR USUÁRIO/MÊS — por escala
A13: Métrica | B13: 100 Usuários | C13: 500 Usuários | D13: 1.000 Usuários | E13: 2.000 Usuários
A14: Custo infra/usuário (USD) | B14: =B10/100 | C14: =C10/500 | D14: =D10/1000 | E14: =E10/2000
A15: Custo infra/usuário (BRL) | B15: =B14*Assumptions!B5 | C15: =C14*Assumptions!B5 | D15: =D14*Assumptions!B5 | E15: =E14*Assumptions!B5
A17: CUSTO STORAGE S3 POR USUÁRIO/MÊS (USD) — por plano
A18: Plano | B18: GB/usuário | C18: USD/usuário/mês | D18: BRL/usuário/mês
A19: Básico | B19: =Assumptions!B32 | C19: =B19*Assumptions!B26 | D19: =C19*Assumptions!B5
A20: Intermediário | B20: =Assumptions!B33 | C20: =B20*Assumptions!B26 | D20: =C20*Assumptions!B5
A21: Pro | B21: =Assumptions!B34 | C21: =B21*Assumptions!B26 | D21: =C21*Assumptions!B5

Sheet Stripe_Costs
A1: CUSTOS STRIPE por Usuário/Mês — Cartão Nacional (Brasil)
A2: 1 transação/mês por usuário (assinatura recorrente). Taxas: Assumptions C.
A3: PLANO MENSAL — Stripe Brasil (3.99% + R$0.39)
A4: Plano | B4: Preço Mensal (BRL) | C4: Taxa % (R$) | D4: Taxa Fixa (R$) | E4: Total Stripe (R$) | F4: % do Preço | G4: Receita Líq. (R$)
A5: Básico | B5: 29.9 | C5: =B5*Assumptions!B16 | D5: =Assumptions!B17 | E5: =C5+D5 | F5: =IF(B5>0,E5/B5,0) | G5: =B5-E5
A6: Intermediário | B6: 59.9 | C6: =B6*Assumptions!B16 | D6: =Assumptions!B17 | E6: =C6+D6 | F6: =IF(B6>0,E6/B6,0) | G6: =B6-E6
A7: Pro | B7: 99.9 | C7: =B7*Assumptions!B16 | D7: =Assumptions!B17 | E7: =C7+D7 | F7: =IF(B7>0,E7/B7,0) | G7: =B7-E7
A9: PLANO ANUAL — Stripe Brasil (1 transação/ano × preço anual com 20% off)
A10: Plano | B10: Preço Anual (BRL) | C10: Taxa % (R$) | D10: Taxa Fixa (R$) | E10: Total Stripe/ano (R$) | F10: Equiv./mês (R$) | G10: % equiv. mensal
A11: Básico | B11: =Stripe_Costs!B5*12*(1-Assumptions!B70) | C11: =B11*Assumptions!B16 | D11: =Assumptions!B17 | E11: =C11+D11 | F11: =E11/12 | G11: =IF(B11>0,F11/(B11/12),0)
A12: Intermediário | B12: =Stripe_Costs!B6*12*(1-Assumptions!B70) | C12: =B12*Assumptions!B16 | D12: =Assumptions!B17 | E12: =C12+D12 | F12: =E12/12 | G12: =IF(B12>0,F12/(B12/12),0)
A13: Pro | B13: =Stripe_Costs!B7*12*(1-Assumptions!B70) | C13: =B13*Assumptions!B16 | D13: =Assumptions!B17 | E13: =C13+D13 | F13: =E13/12 | G13: =IF(B13>0,F13/(B13/12),0)

Sheet Unit_Economics
A1: UNIT ECONOMICS — Custo Total, Preço Sugerido e Margens por Plano
A2: Cenário MODERADO (pior caso para precificação). Infra calculada na escala de referência (Assumptions F B71 = 1.000 usuários).
A3: COST BUILD-UP — CENÁRIO MODERADO (por usuário/mês)
A4: Componente de Custo | B4: Básico (USD) | C4: Básico (BRL) | D4: Intermediário (USD) | E4: Intermediário (BRL) | F4: Pro (USD) | G4: Pro (BRL) | H4: Nota
A5: Custo OpenAI (chat + gerações IA) | B5: =Token_Costs!D15 | C5: =Token_Costs!D15*Assumptions!B5 | D5: =Token_Costs!D30 | E5: =Token_Costs!D30*Assumptions!B5 | F5: =Token_Costs!D45 | G5: =Token_Costs!D45*Assumptions!B5 | H5: Col D de Token_Costs = cenário moderado
A6: Custo Infra/usuário (ref. 1.000 users) | B6: =Infra_Costs!D14 | C6: =Infra_Costs!D14*Assumptions!B5 | D6: =Infra_Costs!D14 | E6: =Infra_Costs!D14*Assumptions!B5 | F6: =Infra_Costs!D14 | G6: =Infra_Costs!D14*Assumptions!B5 | H6: Infra_Costs!D14 = USD/user @ 1.000 users. Altere escala em Assumptions B71.
A7: Custo Storage S3/usuário (por plano) | B7: =Infra_Costs!C19 | C7: =B7*Assumptions!B5 | D7: =Infra_Costs!C20 | E7: =D7*Assumptions!B5 | F7: =Infra_Costs!C21 | G7: =F7*Assumptions!B5 | H7: Infra_Costs col C linhas 19-21 (USD/user)
A8: Custo Stripe (1 cobrança/mês — taxa sobre preço final) | B8: =C8/Assumptions!B5 | C8: =Stripe_Costs!E5 | D8: =E8/Assumptions!B5 | E8: =Stripe_Costs!E6 | F8: =G8/Assumptions!B5 | G8: =Stripe_Costs!E7 | H8: Stripe_Costs!E5:E7 = total taxa mensal (BRL)
A9: CUSTO TOTAL / USUÁRIO / MÊS | B9: =B5+B6+B7+B8 | C9: =B9*Assumptions!B5 | D9: =D5+D6+D7+D8 | E9: =D9*Assumptions!B5 | F9: =F5+F6+F7+F8 | G9: =F9*Assumptions!B5 | H9: OpenAI + Infra + Storage + Stripe
A11: PRECIFICAÇÃO SUGERIDA — Mensal e Anual (BRL e USD)
A12: Parâmetro | B12: Básico BRL | C12: Básico USD | D12: Intermediário BRL | E12: Intermediário USD | F12: Pro BRL | G12: Pro USD | H12: Nota
A13: Preço mensal sugerido — INPUT (BRL) | B13: 29.9 | C13: =B13/Assumptions!B5 | D13: 59.9 | E13: =D13/Assumptions!B5 | F13: 99.9 | G13: =F13/Assumptions!B5 | H13: AMARELO = input editável. Ajuste para ver nova margem.
A14: Margem Bruta (%) | B14: =IF(B13>0,(B13-C9)/B13,0) | C14: ↑ se ≥ 65% | D14: =IF(D13>0,(D13-E9)/D13,0) | E14: ↑ se ≥ 65% | F14: =IF(F13>0,(F13-G9)/F13,0) | G14: ↑ se ≥ 65% | H14: Meta: ≥ Assumptions!B68 (65%)
A15: Receita líquida/usuário/mês após Stripe (BRL) | B15: =B13-(Stripe_Costs!E5) | C15: BRL líq. | D15: =D13-(Stripe_Costs!E6) | E15: BRL líq. | F15: =F13-(Stripe_Costs!E7) | G15: BRL líq.
A16: Preço anual (BRL) — com 20% desconto | B16: =B13*12*(1-Assumptions!B70) | C16: =B16/Assumptions!B5 | D16: =D13*12*(1-Assumptions!B70) | E16: =D16/Assumptions!B5 | F16: =F13*12*(1-Assumptions!B70) | G16: =F16/Assumptions!B5 | H16: Desconto anual: Assumptions B70.
A17: Equivalente mensal do plano anual (BRL) | B17: =B16/12 | C17: =B17/Assumptions!B5 | D17: =D16/12 | E17: =D17/Assumptions!B5 | F17: =F16/12 | G17: =F17/Assumptions!B5
A19: SENSIBILIDADE: Margem Bruta por Escala de Usuários
A20: Plano / Escala | B20: 100 users | C20: 500 users | D20: 1.000 users | E20: 2.000 users
A21: Básico | B21: =IF(B13>0,(B13-((Token_Costs!D15+Infra_Costs!B14+Infra_Costs!C19)*Assumptions!B5+(Stripe_Costs!E5)))/B13,0) | C21: =IF(B13>0,(B13-((Token_Costs!D15+Infra_Costs!C14+Infra_Costs!C19)*Assumptions!B5+(Stripe_Costs!E5)))/B13,0) | D21: =IF(B13>0,(B13-((Token_Costs!D15+Infra_Costs!D14+Infra_Costs!C19)*Assumptions!B5+(Stripe_Costs!E5)))/B13,0) | E21: =IF(B13>0,(B13-((Token_Costs!D15+Infra_Costs!E14+Infra_Costs!C19)*Assumptions!B5+(Stripe_Costs!E5)))/B13,0)
A22: Intermediário | B22: =IF(D13>0,(D13-((Token_Costs!D30+Infra_Costs!B14+Infra_Costs!C20)*Assumptions!B5+(Stripe_Costs!E6)))/D13,0) | C22: =IF(D13>0,(D13-((Token_Costs!D30+Infra_Costs!C14+Infra_Costs!C20)*Assumptions!B5+(Stripe_Costs!E6)))/D13,0) | D22: =IF(D13>0,(D13-((Token_Costs!D30+Infra_Costs!D14+Infra_Costs!C20)*Assumptions!B5+(Stripe_Costs!E6)))/D13,0) | E22: =IF(D13>0,(D13-((Token_Costs!D30+Infra_Costs!E14+Infra_Costs!C20)*Assumptions!B5+(Stripe_Costs!E6)))/D13,0)
A23: Pro | B23: =IF(F13>0,(F13-((Token_Costs!D45+Infra_Costs!B14+Infra_Costs!C21)*Assumptions!B5+(Stripe_Costs!E7)))/F13,0) | C23: =IF(F13>0,(F13-((Token_Costs!D45+Infra_Costs!C14+Infra_Costs!C21)*Assumptions!B5+(Stripe_Costs!E7)))/F13,0) | D23: =IF(F13>0,(F13-((Token_Costs!D45+Infra_Costs!D14+Infra_Costs!C21)*Assumptions!B5+(Stripe_Costs!E7)))/F13,0) | E23: =IF(F13>0,(F13-((Token_Costs!D45+Infra_Costs!E14+Infra_Costs!C21)*Assumptions!B5+(Stripe_Costs!E7)))/F13,0)

Sheet Revenue_Projection
A1: PROJEÇÃO DE RECEITA — Mix: 50% Básico | 35% Intermediário | 15% Pro
A2: Preços da aba Unit_Economics. Mix de planos ajustável nas linhas 5-7.
A3: MIX DE PLANOS — Inputs editáveis
A4: Plano | B4: % do total | C4: Soma (validação) | D4: Nota
A5: Básico | B5: 0.5 | C5: ↓ Deve somar 100%
A6: Intermediário | B6: 0.35 | C6: =B5+B6+B7
A7: Pro | B7: 0.15
A9: RECEITA MENSAL RECORRENTE (MRR) — por Total de Usuários Pagantes
A10: Métrica | B10: 100 users | C10: 250 users | D10: 500 users | E10: 1.000 users | F10: 1.500 users | G10: 2.000 users | H10: 3.000 users | I10: 5.000 users | J10: 10.000 users | K10: Nota
A11: Usuários Básico | B11: =ROUND(100*B5,0) | C11: =ROUND(250*B5,0) | D11: =ROUND(500*B5,0) | E11: =ROUND(1000*B5,0) | F11: =ROUND(1500*B5,0) | G11: =ROUND(2000*B5,0) | H11: =ROUND(3000*B5,0) | I11: =ROUND(5000*B5,0) | J11: =ROUND(10000*B5,0)
A12: Usuários Intermediário | B12: =ROUND(100*B6,0) | C12: =ROUND(250*B6,0) | D12: =ROUND(500*B6,0) | E12: =ROUND(1000*B6,0) | F12: =ROUND(1500*B6,0) | G12: =ROUND(2000*B6,0) | H12: =ROUND(3000*B6,0) | I12: =ROUND(5000*B6,0) | J12: =ROUND(10000*B6,0)
A13: Usuários Pro | B13: =ROUND(100*B7,0) | C13: =ROUND(250*B7,0) | D13: =ROUND(500*B7,0) | E13: =ROUND(1000*B7,0) | F13: =ROUND(1500*B7,0) | G13: =ROUND(2000*B7,0) | H13: =ROUND(3000*B7,0) | I13: =ROUND(5000*B7,0) | J13: =ROUND(10000*B7,0)
A14: MRR Básico (BRL) | B14: =B11*Unit_Economics!B13 | C14: =C11*Unit_Economics!B13 | D14: =D11*Unit_Economics!B13 | E14: =E11*Unit_Economics!B13 | F14: =F11*Unit_Economics!B13 | G14: =G11*Unit_Economics!B13 | H14: =H11*Unit_Economics!B13 | I14: =I11*Unit_Economics!B13 | J14: =J11*Unit_Economics!B13
A15: MRR Intermediário (BRL) | B15: =B12*Unit_Economics!D13 | C15: =C12*Unit_Economics!D13 | D15: =D12*Unit_Economics!D13 | E15: =E12*Unit_Economics!D13 | F15: =F12*Unit_Economics!D13 | G15: =G12*Unit_Economics!D13 | H15: =H12*Unit_Economics!D13 | I15: =I12*Unit_Economics!D13 | J15: =J12*Unit_Economics!D13
A16: MRR Pro (BRL) | B16: =B13*Unit_Economics!F13 | C16: =C13*Unit_Economics!F13 | D16: =D13*Unit_Economics!F13 | E16: =E13*Unit_Economics!F13 | F16: =F13*Unit_Economics!F13 | G16: =G13*Unit_Economics!F13 | H16: =H13*Unit_Economics!F13 | I16: =I13*Unit_Economics!F13 | J16: =J13*Unit_Economics!F13
A17: MRR TOTAL (BRL) | B17: =B14+B15+B16 | C17: =C14+C15+C16 | D17: =D14+D15+D16 | E17: =E14+E15+E16 | F17: =F14+F15+F16 | G17: =G14+G15+G16 | H17: =H14+H15+H16 | I17: =I14+I15+I16 | J17: =J14+J15+J16
A18: MRR TOTAL (USD) | B18: =B17/Assumptions!B5 | C18: =C17/Assumptions!B5 | D18: =D17/Assumptions!B5 | E18: =E17/Assumptions!B5 | F18: =F17/Assumptions!B5 | G18: =G17/Assumptions!B5 | H18: =H17/Assumptions!B5 | I18: =I17/Assumptions!B5 | J18: =J17/Assumptions!B5
A19: ARR (BRL) — × 12 | B19: =B17*12 | C19: =C17*12 | D19: =D17*12 | E19: =E17*12 | F19: =F17*12 | G19: =G17*12 | H19: =H17*12 | I19: =I17*12 | J19: =J17*12
A20: ARR (USD) | B20: =B19/Assumptions!B5 | C20: =C19/Assumptions!B5 | D20: =D19/Assumptions!B5 | E20: =E19/Assumptions!B5 | F20: =F19/Assumptions!B5 | G20: =G19/Assumptions!B5 | H20: =H19/Assumptions!B5 | I20: =I19/Assumptions!B5 | J20: =J19/Assumptions!B5
A22: CUSTO TOTAL MENSAL (COGS) — Cenário Moderado
A23: Métrica | B23: 100 users | C23: 250 users | D23: 500 users | E23: 1.000 users | F23: 1.500 users | G23: 2.000 users | H23: 3.000 users | I23: 5.000 users | J23: 10.000 users | K23: Nota
A24: COGS Básico (BRL) | B24: =B11*Unit_Economics!C9 | C24: =C11*Unit_Economics!C9 | D24: =D11*Unit_Economics!C9 | E24: =E11*Unit_Economics!C9 | F24: =F11*Unit_Economics!C9 | G24: =G11*Unit_Economics!C9 | H24: =H11*Unit_Economics!C9 | I24: =I11*Unit_Economics!C9 | J24: =J11*Unit_Economics!C9
A25: COGS Intermediário (BRL) | B25: =B12*Unit_Economics!E9 | C25: =C12*Unit_Economics!E9 | D25: =D12*Unit_Economics!E9 | E25: =E12*Unit_Economics!E9 | F25: =F12*Unit_Economics!E9 | G25: =G12*Unit_Economics!E9 | H25: =H12*Unit_Economics!E9 | I25: =I12*Unit_Economics!E9 | J25: =J12*Unit_Economics!E9
A26: COGS Pro (BRL) | B26: =B13*Unit_Economics!G9 | C26: =C13*Unit_Economics!G9 | D26: =D13*Unit_Economics!G9 | E26: =E13*Unit_Economics!G9 | F26: =F13*Unit_Economics!G9 | G26: =G13*Unit_Economics!G9 | H26: =H13*Unit_Economics!G9 | I26: =I13*Unit_Economics!G9 | J26: =J13*Unit_Economics!G9
A27: COGS TOTAL (BRL) | B27: =B24+B25+B26 | C27: =C24+C25+C26 | D27: =D24+D25+D26 | E27: =E24+E25+E26 | F27: =F24+F25+F26 | G27: =G24+G25+G26 | H27: =H24+H25+H26 | I27: =I24+I25+I26 | J27: =J24+J25+J26
A29: LUCRO BRUTO MENSAL (MRR - COGS)
A30: Métrica | B30: 100 users | C30: 250 users | D30: 500 users | E30: 1.000 users | F30: 1.500 users | G30: 2.000 users | H30: 3.000 users | I30: 5.000 users | J30: 10.000 users | K30: Nota
A31: Lucro Bruto (BRL) | B31: =B17-B27 | C31: =C17-C27 | D31: =D17-D27 | E31: =E17-E27 | F31: =F17-F27 | G31: =G17-G27 | H31: =H17-H27 | I31: =I17-I27 | J31: =J17-J27
A32: Margem Bruta (%) | B32: =IF(B17>0,B31/B17,0) | C32: =IF(C17>0,C31/C17,0) | D32: =IF(D17>0,D31/D17,0) | E32: =IF(E17>0,E31/E17,0) | F32: =IF(F17>0,F31/F17,0) | G32: =IF(G17>0,G31/G17,0) | H32: =IF(H17>0,H31/H17,0) | I32: =IF(I17>0,I31/I17,0) | J32: =IF(J17>0,J31/J17,0)

Sheet Recalc_Guide
A1: GUIA DE RECÁLCULO MENSAL — Shape Certo SaaS
A2: Execute este checklist mensalmente ou sempre que houver mudança de preço em APIs, câmbio ou infraestrutura.
A3: # | B3: Ação | C3: Onde Atualizar (aba → célula) | D3: Impacto Automático
A4: 1 | B4: Atualizar câmbio USD → BRL | C4: Assumptions → B5 | D4: Todos os custos BRL, preços USD e margens recalculam automaticamente
A5: 2 | B5: Mover câmbio atual para 'mês anterior' antes de atualizar | C5: Assumptions → B6 (câmbio anterior) | D5: B7 (variação câmbio %) calcula automaticamente
A6: 3 | B6: Verificar preço OpenAI Input (USD/1M tk) | C6: Assumptions → B11 | D6: Token_Costs → Unit_Economics → Revenue_Projection (cascata completa)
A7: 4 | B7: Verificar preço OpenAI Output (USD/1M tk) | C7: Assumptions → B12 | D7: Idem cascata acima
A8: 5 | B8: Verificar taxa % Stripe Brasil | C8: Assumptions → B16 | D8: Stripe_Costs recalcula → Unit_Economics (custo Stripe) → margens
A9: 6 | B9: Verificar taxa fixa Stripe (R$) | C9: Assumptions → B17 | D9: Idem acima
A10: 7 | B10: Revisar custos de infra (servidor, DB, S3, CDN, monitoring) | C10: Assumptions → B23:B28 | D10: Infra_Costs recalcula → Unit_Economics → Revenue_Projection
A11: 8 | B11: Revisar preços sugeridos se margem caiu < 65% | C11: Unit_Economics → B13, D13, F13 (células AMARELAS) | D11: Margens, Stripe_Costs B5:B7 e Revenue_Projection recalculam
A12: 9 | B12: Sincronizar preços em Stripe_Costs manualmente (sem link automático — evita circularidade) | C12: Stripe_Costs → B5, B6, B7 | D12: Stripe_Costs recalcula custo por transação → Unit_Economics
A13: 10 | B13: Verificar mix de planos se base de usuários mudou | C13: Revenue_Projection → B5, B6, B7 | D13: Revenue_Projection inteiro recalcula (MRR, ARR, COGS, margem)
A14: 11 | B14: Revisar tokens de contexto se backend mudou compressão | C14: Assumptions → B38, B39, B40 | D14: Token_Costs e Unit_Economics recalculam
A15: 12 | B15: Atualizar frequência de uso com dados reais de analytics | C15: Assumptions → B56:C58 (msgs/dia) e B62:C64 (gerações/mês) | D15: Token_Costs, Unit_Economics e Revenue_Projection recalculam
... A17: 14 | B17: Atualizar data de última revisão no título da aba Assumptions | C17: Assumptions → A2 (texto da data) | D17: Rastreabilidade de quando o modelo foi revisado
A19: IMPORTANTE: Por Que Stripe_Costs!B5:B7 São Inputs Independentes (Não Linkados)
A20: • Os preços em Stripe_Costs!B5:B7 NÃO são linkados automaticamente de Unit_Economics — isso é intencional.
A21: • Motivo: Stripe cost depende do preço → preço depende do Stripe cost = referência circular.
A22: • Fluxo correto: 1) Altere preço em Unit_Economics (célula amarela) → 2) Verifique nova margem → 3) Se ok, atualize Stripe_Costs B5:B7 → 4) Verifique margem final.
A23: • Diferença é pequena: Stripe cost em 1 iteração já é muito próximo do valor convergido (R$1–R$4 de diferença).

Sheet Summary_Dashboard
A1: SHAPE CERTO — SUMÁRIO EXECUTIVO DO PLANO DE NEGÓCIOS
A2: Câmbio: USD 1 = R$ 5,70 (Mai 2026) | Todos os valores linkados automaticamente das abas de cálculo
A3: PREÇOS E MARGENS — Cenário Moderado @ 1.000 usuários
A4: Plano | B4: Preço Mensal (BRL) | C4: Preço Anual (BRL) | D4: Custo Total/Usuário (BRL) | E4: Margem Bruta (%)
A5: Básico | B5: =Unit_Economics!B13 | C5: =Unit_Economics!B16 | D5: =Unit_Economics!C9 | E5: =Unit_Economics!B14
A6: Intermediário | B6: =Unit_Economics!D13 | C6: =Unit_Economics!D16 | D6: =Unit_Economics!E9 | E6: =Unit_Economics!D14
A7: Pro | B7: =Unit_Economics!F13 | C7: =Unit_Economics!F16 | D7: =Unit_Economics!G9 | E7: =Unit_Economics!F14
A9: RECEITA PROJETADA — Mix 50/35/15 (valores mensais)
A10: Escala (Usuários) | B10: MRR (BRL) | C10: ARR (BRL) | D10: COGS (BRL) | E10: Lucro Bruto (BRL)
A11: 100 usuários | B11: =Revenue_Projection!B17 | C11: =Revenue_Projection!B19 | D11: =Revenue_Projection!B27 | E11: =Revenue_Projection!B31
A12: 500 usuários | B12: =Revenue_Projection!D17 | C12: =Revenue_Projection!D19 | D12: =Revenue_Projection!D27 | E12: =Revenue_Projection!D31
A13: 1.000 usuários | B13: =Revenue_Projection!E17 | C13: =Revenue_Projection!E19 | D13: =Revenue_Projection!E27 | E13: =Revenue_Projection!E31
A14: 2.000 usuários | B14: =Revenue_Projection!G17 | C14: =Revenue_Projection!G19 | D14: =Revenue_Projection!G27 | E14: =Revenue_Projection!G31
A15: 5.000 usuários | B15: =Revenue_Projection!I17 | C15: =Revenue_Projection!I19 | D15: =Revenue_Projection!I27 | E15: =Revenue_Projection!I31
A16: 10.000 usuários | B16: =Revenue_Projection!J17 | C16: =Revenue_Projection!J19 | D16: =Revenue_Projection!J27 | E16: =Revenue_Projection!J31
A18: CUSTO OPENAI POR USUÁRIO/MÊS — Conservador vs. Moderado
A19: Plano | B19: Conservador (USD) | C19: Moderado (USD) | D19: Conservador (BRL) | E19: Moderado (BRL)
A20: Básico | B20: =Token_Costs!C15 | C20: =Token_Costs!D15 | D20: =Token_Costs!G15 | E20: =Token_Costs!H15
A21: Intermediário | B21: =Token_Costs!C30 | C21: =Token_Costs!D30 | D21: =Token_Costs!G30 | E21: =Token_Costs!H30
A22: Pro | B22: =Token_Costs!C45 | C22: =Token_Costs!D45 | D22: =Token_Costs!G45 | E22: =Token_Costs!H45
A24: INFRA: CUSTO POR USUÁRIO CONFORME ESCALA
A25: Escala | B25: Infra/usuário (USD) | C25: Infra/usuário (BRL) | D25: Total Infra/mês (USD) | E25: Nota
A26: 100 usuários | B26: =Infra_Costs!B14 | C26: =Infra_Costs!B14*Assumptions!B5 | D26: =Infra_Costs!B10 | E26: Fonte: Infra_Costs
A27: 500 usuários | B27: =Infra_Costs!C14 | C27: =Infra_Costs!C14*Assumptions!B5 | D27: =Infra_Costs!C10 | E27: Fonte: Infra_Costs
A28: 1.000 usuários | B28: =Infra_Costs!D14 | C28: =Infra_Costs!D14*Assumptions!B5 | D28: =Infra_Costs!D10 | E28: Fonte: Infra_Costs
A29: 2.000 usuários | B29: =Infra_Costs!E14 | C29: =Infra_Costs!E14*Assumptions!B5 | D29: =Infra_Costs!E10 | E29: Fonte: Infra_Costs
